Workbook

Sheet Review Summary
A1: TrueBind review
A2: File | B2: Sample_Bordereau.xlsx
A3: Verdict | B3: Fix before submitting
A5: Count | B5: Findings
A6: Errors | B6: =COUNTIFS(Issues!$B:$B,"Error")
A7: Warnings | B7: =COUNTIFS(Issues!$B:$B,"Warning")
A8: Couldn't check | B8: =COUNTIFS(Issues!$B:$B,"Couldn't check")
A10: Issue | B10: Errors | C10: Warnings | D10: Couldn't check
A11: Closed claim still holds a reserve | B11: =COUNTIFS(Issues!$A:$A,"Closed claim still holds a reserve",Issues!$B:$B,"Error") | C11: =COUNTIFS(Issues!$A:$A,"Closed claim still holds a reserve",Issues!$B:$B,"Warning") | D11: =COUNTIFS(Issues!$A:$A,"Closed claim still holds a reserve",Issues!$B:$B,"Couldn't check")
A12: Currency code not recognised | B12: =COUNTIFS(Issues!$A:$A,"Currency code not recognised",Issues!$B:$B,"Error") | C12: =COUNTIFS(Issues!$A:$A,"Currency code not recognised",Issues!$B:$B,"Warning") | D12: =COUNTIFS(Issues!$A:$A,"Currency code not recognised",Issues!$B:$B,"Couldn't check")
A13: Currency written non-standardly | B13: =COUNTIFS(Issues!$A:$A,"Currency written non-standardly",Issues!$B:$B,"Error") | C13: =COUNTIFS(Issues!$A:$A,"Currency written non-standardly",Issues!$B:$B,"Warning") | D13: =COUNTIFS(Issues!$A:$A,"Currency written non-standardly",Issues!$B:$B,"Couldn't check")
A14: Date stored as text or a number | B14: =COUNTIFS(Issues!$A:$A,"Date stored as text or a number",Issues!$B:$B,"Error") | C14: =COUNTIFS(Issues!$A:$A,"Date stored as text or a number",Issues!$B:$B,"Warning") | D14: =COUNTIFS(Issues!$A:$A,"Date stored as text or a number",Issues!$B:$B,"Couldn't check")
A15: Exact duplicate | B15: =COUNTIFS(Issues!$A:$A,"Exact duplicate",Issues!$B:$B,"Error") | C15: =COUNTIFS(Issues!$A:$A,"Exact duplicate",Issues!$B:$B,"Warning") | D15: =COUNTIFS(Issues!$A:$A,"Exact duplicate",Issues!$B:$B,"Couldn't check")
A16: Incurred exceeds the policy limit | B16: =COUNTIFS(Issues!$A:$A,"Incurred exceeds the policy limit",Issues!$B:$B,"Error") | C16: =COUNTIFS(Issues!$A:$A,"Incurred exceeds the policy limit",Issues!$B:$B,"Warning") | D16: =COUNTIFS(Issues!$A:$A,"Incurred exceeds the policy limit",Issues!$B:$B,"Couldn't check")
A17: Loss outside the policy period | B17: =COUNTIFS(Issues!$A:$A,"Loss outside the policy period",Issues!$B:$B,"Error") | C17: =COUNTIFS(Issues!$A:$A,"Loss outside the policy period",Issues!$B:$B,"Warning") | D17: =COUNTIFS(Issues!$A:$A,"Loss outside the policy period",Issues!$B:$B,"Couldn't check")
A18: Negative reserve | B18: =COUNTIFS(Issues!$A:$A,"Negative reserve",Issues!$B:$B,"Error") | C18: =COUNTIFS(Issues!$A:$A,"Negative reserve",Issues!$B:$B,"Warning") | D18: =COUNTIFS(Issues!$A:$A,"Negative reserve",Issues!$B:$B,"Couldn't check")
A19: Notified before the loss date | B19: =COUNTIFS(Issues!$A:$A,"Notified before the loss date",Issues!$B:$B,"Error") | C19: =COUNTIFS(Issues!$A:$A,"Notified before the loss date",Issues!$B:$B,"Warning") | D19: =COUNTIFS(Issues!$A:$A,"Notified before the loss date",Issues!$B:$B,"Couldn't check")
A20: Paid exceeds total incurred | B20: =COUNTIFS(Issues!$A:$A,"Paid exceeds total incurred",Issues!$B:$B,"Error") | C20: =COUNTIFS(Issues!$A:$A,"Paid exceeds total incurred",Issues!$B:$B,"Warning") | D20: =COUNTIFS(Issues!$A:$A,"Paid exceeds total incurred",Issues!$B:$B,"Couldn't check")
A21: Probable duplicate | B21: =COUNTIFS(Issues!$A:$A,"Probable duplicate",Issues!$B:$B,"Error") | C21: =COUNTIFS(Issues!$A:$A,"Probable duplicate",Issues!$B:$B,"Warning") | D21: =COUNTIFS(Issues!$A:$A,"Probable duplicate",Issues!$B:$B,"Couldn't check")
A22: Required data missing | B22: =COUNTIFS(Issues!$A:$A,"Required data missing",Issues!$B:$B,"Error") | C22: =COUNTIFS(Issues!$A:$A,"Required data missing",Issues!$B:$B,"Warning") | D22: =COUNTIFS(Issues!$A:$A,"Required data missing",Issues!$B:$B,"Couldn't check")
A23: Status not recognised | B23: =COUNTIFS(Issues!$A:$A,"Status not recognised",Issues!$B:$B,"Error") | C23: =COUNTIFS(Issues!$A:$A,"Status not recognised",Issues!$B:$B,"Warning") | D23: =COUNTIFS(Issues!$A:$A,"Status not recognised",Issues!$B:$B,"Couldn't check")
A24: Total incurred does not reconcile | B24: =COUNTIFS(Issues!$A:$A,"Total incurred does not reconcile",Issues!$B:$B,"Error") | C24: =COUNTIFS(Issues!$A:$A,"Total incurred does not reconcile",Issues!$B:$B,"Warning") | D24: =COUNTIFS(Issues!$A:$A,"Total incurred does not reconcile",Issues!$B:$B,"Couldn't check")
A26: Legend
B27: Checked: no issue found
B28: Unusual, or could not be validated (for example a date held as text)
A29: Error | B29: Error: must be fixed before the file is sent
B30: Structural row (header, title, subtotal, blank), not a claim
A32: Hover over an amber or red cell to see what was found and how to fix it. Every row also has a Review notes column. Values in your sheets are exactly as received.

Sheet Claims
A1: Monthly claims bordereau - synthetic sample (no real data)
A2: Claim Ref | B2: Pol No. | C2: Insured Name | D2: Inception | E2: Expiry | F2: Policy Limit | G2: Date of Loss | H2: Date Rptd | I2: Claim Status | J2: Currency | K2: Paid to Date | L2: Outstanding Reserve | M2: Total Incurred | N2: Review notes
A3: CLM-100000 | B3: 4500436 | C3: Kestrel Garages Limited | D3: 45998 | E3: 46362 | F3: 100000 | G3: 46108 | H3: 46136 | I3: Open | J3: EUR | K3: 5754.26 | L3: 42827.08 | M3: 48581.34 | N3: OK
A4: CLM-100007 | B4: 4895715 | C4: Ellery Motors Limited | D4: 45771 | E4: 46135 | F4: 100000 | G4: 45985 | H4: 45998 | I4: Closed | J4: GBP | K4: 29999.7 | L4: 0 | M4: 29999.7 | N4: OK
A5: CLM-100014 | B5: 4885702 | C5: Oakham Electrical Ltd | D5: 45946 | E5: 46310 | F5: 100000 | G5: 45927 | H5: 45932 | I5: Open | J5: USD | K5: 1367.21 | L5: 33297.22 | M5: 34664.43 | N5: Error: Loss outside the policy period: date of loss 2025-09-27 is before policy inception 2025-10-16.
A6: CLM-100021 | B6: 4444022 | C6: Kilbride Builders Ltd | D6: 45678 | E6: 46042 | F6: 500000 | G6: 45686 | H6: 45716 | I6: Open | J6: GBP | K6: 48956.74 | L6: 68165.61 | M6: 117122.35 | N6: OK
A7: CLM-100028 | B7: 4571408 | C7: Oakham Logistics Ltd | D7: 45767 | E7: 46131 | F7: 250000 | G7: 45968 | H7: 45996 | I7: Open | J7: EUR | K7: 3535.01 | L7: 6453.82 | M7: 9988.83 | N7: OK
A8: CLM-100035 | B8: 4821811 | C8: Kestrel Joinery LLP | D8: 45759 | E8: 46123 | F8: 500000 | G8: 46069 | H8: 46075 | I8: Closed | J8: EUR | K8: 6251.11 | L8: 0 | M8: 6251.11 | N8: OK
A9: CLM-100042 | B9: 4711686 | C9: Fenwick Engineering Holdings | D9: 45933 | E9: 46297 | F9: 250000 | G9: 45958 | H9: 45981 | I9: Open | J9: USD | K9: 47597.25 | L9: 76913.06 | M9: 124510.31 | N9: OK
A10: CLM-100049 | B10: 4159317 | C10: Pembroke Freight Group | D10: 45984 | E10: 46348 | F10: 1000000 | G10: 46212 | H10: 46235 | I10: Open | J10: GBP | K10: 42659.98 | L10: 77336.26 | M10: 119996.24 | N10: OK
A11: CLM-100056 | B11: 4051061 | C11: Galway Joinery Limited | D11: 45957 | E11: 46321 | F11: 100000 | G11: 46205 | H11: 46208 | I11: Open | J11: GBP | K11: 31262.62 | L11: 36458.89 | M11: 67721.51 | N11: OK
A12: CLM-100063 | B12: 4443853 | C12: Oakham Freight Holdings | D12: 45783 | E12: 46147 | F12: 100000 | G12: 45838 | H12: 45843 | I12: Open | J12: GBP | K12: 39599.1 | L12: 38079.93 | M12: 77679.03 | N12: OK
A13: CLM-100070 | B13: 4216938 | C13: Larkspur Textiles plc | D13: 45896 | E13: 46260 | F13: 100000 | G13: 46065 | H13: 46101 | I13: Closed | J13: GBP | K13: 4528.3 | L13: 0 | M13: 4528.3 | N13: OK
A14: CLM-100077 | B14: 4085440 | C14: Northcote Bakery LLP | D14: 45743 | E14: 46107 | F14: 1000000 | G14: 46053 | H14: 46086 | I14: Reopened | J14: GBP | K14: 37409.12 | L14: 25646.58 | M14: 63055.7 | N14: OK
... A163: CLM-101120 | B163: 4534973 | C163: Upton Logistics Holdings | D163: 45683 | E163: 46047 | F163: 250000 | G163: 45947 | H163: 45963 | I163: Open | J163: GBP | K163: 35214.36 | L163: 23447.36 | M163: 58661.72 | N163: OK
A164: CLM-101127 | B164: 4151690 | C164: Brennan Freight LLP | D164: 45712 | E164: 46076 | F164: 100000 | G164: 25 Apr 2025 | H164: 45777 | I164: Open | J164: GBP | K164: 37730.78 | L164: 15171.73 | M164: 52902.51 | N164: Warning: Date stored as text or a number: date of loss 2025-04-25 was read from text or an Excel serial number, not a date cell.
A165: CLM-101134 | B165: 4624438 | C165: Merrow Builders plc | D165: 45816 | E165: 46180 | F165: 500000 | G165: 45826 | H165: 45828 | I165: Open | J165: USD | K165: 40937.62 | L165: 44299.95 | M165: 85237.57 | N165: OK
A166: CLM-101141 | B166: 4655374 | C166: Norland Florists & Sons | D166: 45706 | E166: 46070 | F166: 500000 | G166: 45799 | H166: 45836 | I166: Open | J166: GBP | K166: 11475.69 | L166: 30839.69 | M166: 42315.38 | N166: OK
A167: CLM-101148 | B167: 4361069 | C167: Ashby Haulage & Sons | D167: 45902 | E167: 46266 | F167: 100000 | G167: 45962 | H167: 45994 | I167: Closed | J167: GBP | K167: 10775.21 | L167: 0 | M167: 10775.21 | N167: OK
A168: CLM-101155 | B168: 4548296 | C168: Pembroke Engineering Group | D168: 45812 | E168: 46176 | F168: 1000000 | G168: 45924 | H168: 45942 | I168: Open | J168: EUR | K168: 44786.23 | L168: 52510.42 | M168: 97296.65 | N168: OK
A169: CLM-101162 | B169: 4682068 | C169: Larkspur Pharmacy Limited | D169: 45664 | E169: 46028 | F169: 1000000 | G169: 45970 | H169: 46003 | I169: Open | J169: GBP | K169: 11137.84 | L169: 953.71 | M169: 12091.55 | N169: OK
A170: CLM-101169 | B170: 4745855 | C170: Upton Marine Ltd | D170: 45834 | E170: 46198 | F170: 1000000 | G170: 45894 | H170: 45923 | I170: Open | J170: GBP | K170: 41427.48 | L170: 6790.48 | M170: 48217.96 | N170: OK
A171: CLM-101176 | B171: 4291303 | C171: Dunmore Print Limited | D171: 45780 | E171: 46144 | F171: 100000 | G171: 45950 | H171: 45958 | I171: Closed | J171: GBP | K171: 31415.51 | L171: 0 | M171: 31415.51 | N171: OK
A172: CLM-101183 | B172: 4260247 | C172: Merrow Pharmacy plc | D172: 45891 | E172: 46255 | F172: 100000 | G172: 46058 | H172: 46084 | I172: Open | J172: USD | K172: 39273.1 | L172: 3760.44 | M172: 43033.54 | N172: OK
A173: CLM-101190 | B173: 4249069 | C173: Upton Motors Holdings | D173: 45756 | E173: 46120 | F173: 250000 | G173: 45944 | H173: 45967 | I173: Closed | J173: GBP | K173: 36072.75 | L173: 0 | M173: 36072.75 | N173: OK
A174: CLM-101197 | B174: 4597504 | C174: Ellery Farms Limited | D174: 45834 | E174: 46198 | F174: 250000 | G174: 46150 | H174: 46190 | I174: Open | J174: GBP | K174: 45203.43 | L174: 29774.99 | M174: 74978.42 | N174: OK
A175: CLM-101204 | B175: 4401217 | C175: Merrow Garages Limited | D175: 45872 | E175: 46236 | F175: 500000 | G175: 46077 | H175: 46078 | I175: Open | J175: EUR | K175: 16679.13 | L175: 59328.31 | M175: 76007.44 | N175: OK
A176: CLM-101211 | B176: 4656370 | C176: Inglewood Print LLP | D176: 46009 | E176: 46373 | F176: 100000 | G176: 46031 | H176: 46038 | I176: Closed | J176: EUR | K176: 31378.52 | L176: 0 | M176: 31378.52 | N176: OK
... A415: CLM-102884 | B415: 4595253 | C415: Upton Garages Limited | D415: 45890 | E415: 46254 | F415: 100000 | G415: 46022 | H415: 46046 | I415: Closed | J415: GBP | K415: 17121.98 | L415: 0 | M415: 17121.98 | N415: OK
A416: CLM-102891 | B416: 4307284 | D416: 45913 | E416: 46277 | F416: 250000 | G416: 46094 | H416: 46127 | I416: Closed | J416: GBP | K416: 39659.85 | L416: 0 | M416: 39659.85 | N416: Error: Required data missing: insured name is missing.
A417: CLM-102898 | B417: 4834933 | C417: Kestrel Foods Ltd | D417: 45764 | E417: 46128 | F417: 500000 | G417: 45861 | H417: 45871 | I417: Open | J417: GBP | K417: 57591.05 | L417: 15232.97 | M417: 72824.02 | N417: OK
A418: CLM-102905 | B418: 4362719 | C418: Ballina Hotels Limited | D418: 45906 | E418: 46270 | F418: 500000 | G418: 46065 | H418: 46087 | I418: Open | J418: GBP | K418: 51750.86 | L418: 72623.24 | M418: 124374.1 | N418: OK
A419: CLM-102912 | B419: 4066984 | C419: Galway Pharmacy LLP | D419: 45698 | E419: 46062 | F419: 500000 | G419: 45881 | H419: 45900 | I419: Closed | J419: GBP | K419: 50874.3 | L419: 0 | M419: 50874.3 | N419: OK
A420: CLM-102919 | B420: 4535989 | C420: Larkspur Garages & Sons | D420: 45931 | E420: 46295 | F420: 1000000 | G420: 46179 | H420: 46212 | I420: Closed | J420: GBP | K420: 56519.42 | L420: 0 | M420: 56519.42 | N420: OK
A421: CLM-102926 | B421: 4258535 | C421: Galway Electrical Limited | D421: 45851 | E421: 46215 | F421: 1000000 | G421: 45870 | H421: 45907 | I421: Open | J421: GBP | K421: 55225.79 | L421: 45026.16 | M421: 100251.95 | N421: OK
A422: CLM-102933 | B422: 4856477 | C422: Thornbury Haulage plc | D422: 45862 | E422: 46226 | F422: 100000 | G422: 45925 | H422: 45951 | I422: Open | J422: GBP | K422: 11008.19 | L422: 14619.89 | M422: 25628.08 | N422: OK
A423: CLM-102940 | B423: 4707665 | C423: Pembroke Print Group | D423: 45983 | E423: 46347 | F423: 1000000 | G423: 46285 | H423: 46292 | I423: Closed | J423: USD | K423: 7411.59 | L423: 0 | M423: 7411.59 | N423: OK
A424: CLM-102947 | B424: 4408326 | C424: Kilbride Marine LLP | D424: 45962 | E424: 46326 | F424: 100000 | G424: 46262 | H424: 46285 | I424: Open | J424: USD | K424: 30328.7 | L424: 20671.36 | M424: 51000.06 | N424: OK
A425: CLM-102954 | B425: 4071968 | C425: Thornbury Freight Group | D425: 45854 | E425: 46218 | F425: 250000 | G425: 45871 | H425: 45901 | I425: Closed | J425: EUR | K425: 35986.7 | L425: 0 | M425: 35986.7 | N425: OK
A426: CLM-102961 | B426: 4340505 | C426: Harbour Garages & Sons | D426: 45836 | E426: 46200 | F426: 500000 | G426: 45979 | H426: 45990 | I426: Open | J426: GBP | K426: 52823.78 | L426: 50403.88 | M426: 103227.66 | N426: OK
...

Sheet Summary
A1: Status | B1: Claims | C1: Total incurred
A2: Open | B2: 374 | C2: 23988706
A3: Closed | B3: 101 | C3: 3005079.2
A4: Reopened | B4: 26 | C4: 1650458.4

Sheet Notes
A1: Prepared by the claims team. Figures in policy currency.

Sheet Issues
A1: Issue | B1: Result | C1: Severity | D1: Where (click to go) | E1: Claim reference | F1: What we found | G1: Fix | H1: Who fixes
A2: Required data missing (2)
A3: Required data missing | B3: Error | C3: Critical | D3: Claims!C416 | E3: CLM-102891 | F3: Required data missing: insured name is missing. | G3: Ask the sender for the missing value. | H3: Sender
A4: Required data missing | B4: Error | C4: Critical | D4: Claims!C499 | E4: CLM-103472 | F4: Required data missing: insured name is missing. | G4: Ask the sender for the missing value. | H4: Sender
A5: Currency code not recognised (1)
A6: Currency code not recognised | B6: Error | C6: High | D6: Claims!J107 | E6: CLM-100728 | F6: Currency code not recognised: 'XXX' is not a valid ISO 4217 code. | G6: Use a valid ISO currency code (EUR, GBP, USD...). Confirm which currency the amounts are in. | H6: Sender
A7: Exact duplicate (1)
A8: Exact duplicate | B8: Error | C8: High | D8: Claims!A409 | E8: CLM-102842 | F8: Exact duplicate: claim reference 'CLM-102842' is repeated with identical amounts and status in the same sheet 'Claims' (no reporting period present). | G8: The same claim was sent twice with identical figures. Ask the sender to withdraw one. | H8: Sender
A9: Incurred exceeds the policy limit (1)
A10: Incurred exceeds the policy limit | B10: Error | C10: High | D10: Claims!M22 | E10: CLM-100133 | F10: Incurred exceeds the policy limit: total incurred 150,000.00 is above the policy limit 100,000.00. | G10: Total incurred is above the policy limit: a possible overpayment or a wrong limit. Check both. | H10: Sender
A11: Loss outside the policy period (1)
A12: Loss outside the policy period | B12: Error | C12: High | D12: Claims!G5 | E12: CLM-100014 | F12: Loss outside the policy period: date of loss 2025-09-27 is before policy inception 2025-10-16. | G12: The date of loss is before inception or after expiry. Check the dates and the policy. | H12: Sender
A13: Negative reserve (1)
A14: Negative reserve | B14: Error | C14: High | D14: Claims!L479 | E14: CLM-103332 | F14: Negative reserve: reserve is -1,841.16; a reserve cannot be negative. | G14: Reserves cannot be negative. Ask the sender for the correct outstanding amount. | H14: Sender
A15: Paid exceeds total incurred (1)
A16: Paid exceeds total incurred | B16: Error | C16: High | D16: Claims!K479 | E16: CLM-103332 | F16: Paid exceeds total incurred: paid to date 19,147.98 is more than total incurred 17,306.82. | G16: Paid to date cannot be more than total incurred. Ask the sender to correct the figures. | H16: Sender
A17: Total incurred does not reconcile (2)
A18: Total incurred does not reconcile | B18: Error | C18: High | D18: Claims!M458 | E18: CLM-103185 | F18: Total incurred does not reconcile: total incurred=58,702.08 but paid to date 26,451.11 + reserve 36,367.57 = 62,818.68 (no fee columns in this file: checked as nil fees; if the total includes fees the difference may be fees). | G18: Total incurred should equal paid plus reserve (plus fees). Ask the sender which figure is right. | H18: Sender
A19: Total incurred does not reconcile | B19: Error | C19: High | D19: Claims!M480 | E19: CLM-103339 | F19: Total incurred does not reconcile: total incurred=88,638.40 but paid to date 19,256.61 + reserve 73,580.85 = 92,837.46 (no fee columns in this file: checked as nil fees; if the total includes fees the difference may be fees). | G19: Total incurred should equal paid plus reserve (plus fees). Ask the sender which figure is right. | H19: Sender
A20: Notified before the loss date (1)
A21: Notified before the loss date | B21: Error | C21: Medium | D21: Claims!H67 | E21: CLM-100448 | F21: Notified before the loss date: date of loss 2026-01-17 is after date first notified 2026-01-01. | G21: The claim was notified before it happened. Check both dates with the sender. | H21: Sender
A22: Status not recognised (1)
A23: Status not recognised | B23: Error | C23: Medium | D23: Claims!I287 | E23: CLM-101988 | F23: Status not recognised: 'in litigation hold' is not one of ['cancelled', 'closed', 'ntu', 'open', 'other', 'reopened', 'void', 'withdrawn']. | G23: Use one of the agreed statuses (Open, Closed, Reopened...), or add it to the accepted list. | H23: Sender
A24: Closed claim still holds a reserve (2)
A25: Closed claim still holds a reserve | B25: Warning | C25: Medium | D25: Claims!L22 | E25: CLM-100133 | F25: Closed claim still holds a reserve: claim is closed but still holds a reserve of 60,000.00. | G25: A closed or settled claim should hold no reserve. Ask the sender to release it or reopen the claim. | H25: Sender
A26: Closed claim still holds a reserve | B26: Warning | C26: Medium | D26: Claims!L391 | E26: CLM-102716 | F26: Closed claim still holds a reserve: claim is closed but still holds a reserve of 1,500.00. | G26: A closed or settled claim should hold no reserve. Ask the sender to release it or reopen the claim. | H26: Sender
A27: Probable duplicate (1)
A28: Probable duplicate | B28: Warning | C28: Medium | D28: Claims!A304 | E28: CLM-102107 | F28: Probable duplicate: 100% confidence: insured names 'Ballina Florists Limited' / 'Ballina Florists Limited' are 100% similar, loss dates 2025-11-13 / 2025-11-13 are 0 days apart, claim references differ; policy references match; amounts are the same. | G28: Compare the two rows side by side; confirm whether they are the same loss. | H28: Sender
A29: Currency written non-standardly (1)
A30: Currency written non-standardly | B30: Warning | C30: Info | D30: Claims!J74 | E30: CLM-100497 | F30: Currency written non-standardly: 'eur' read as EUR. | G30: Read as the ISO code shown. The corrected copy writes the ISO code. | H30: Us
A31: Date stored as text or a number (1)
A32: Date stored as text or a number | B32: Warning | C32: Info | D32: Claims!G164 | E32: CLM-101127 | F32: Date stored as text or a number: date of loss 2025-04-25 was read from text or an Excel serial number, not a date cell. | G32: Read correctly, but stored as text or an Excel serial number. The corrected copy converts it to a real date. | H32: Us
